#VRML_SIM R2022a utf8
WorldInfo {
  info [
    "created by Anna Astolfi 02/03/2020 a.astolfi^santannapisa.it"
  ]
  title "seabed"
  window "generic"
  basicTimeStep 4
  coordinateSystem "NUE"
}
Viewpoint {
  fieldOfView 1.1
  orientation -0.5773502691896258 0.5773502691896257 0.5773502691896258 2.0943951023931953
  position 3.994065788503808e-06 0.2618398871115897 1.3688396303518007
  near 0.01
  exposure 1.5
  ambientOcclusionRadius 4
}
TexturedBackground {
}
TexturedBackgroundLight {
}
DEF foot Floor {
  rotation -0.5773502691896258 0.5773502691896258 0.5773502691896258 2.0943951023931953
  size 15 15
}
DEF tank SolidPipe {
  translation 0 0.75 0
  rotation -0.5773502691896258 0.5773502691896258 0.5773502691896258 2.0943951023931953
  height 1.5
  radius 4.3
  thickness 0.3
  subdivision 80
  appearance PBRAppearance {
    baseColor 0.5 0.5 0.5
    transparency 1
    roughness 1.11e-16
    metalness 0
  }
}
Solid {
  translation 0 1.5 0
  rotation 1 0 0 1.57
  children [
    Shape {
      appearance PBRAppearance {
        baseColor 0 0 0
        transparency 0.5
        metalness 0
      }
      geometry Cylinder {
        height 0.1
        radius 4.3
      }
    }
  ]
}
DEF water Fluid {
  translation 0 0.75 0
  rotation 1 0 0 1.57
  children [
    DEF Filling Shape {
      appearance DEF water_like PBRAppearance {
        baseColor 0 0.5 0.9
        transparency 0.5
        roughness 1.11e-16
        metalness 0
      }
      geometry Cylinder {
        height 1.5
        radius 4
      }
    }
  ]
  name "water tank"
  boundingObject USE Filling
}
DEF uw_gripper Robot {
  children [
    Transform {
      translation 0 0.025 0
      rotation 1 0 0 -1.57
      children [
        DEF base Shape {
          appearance PBRAppearance {
            metalness 0
          }
          geometry Cylinder {
            height 0.05
            radius 0.2
          }
        }
        DEF hj_shoulder1 HingeJoint {
          jointParameters HingeJointParameters {
            axis 0 0 1
          }
          device [
            RotationalMotor {
              name "motor0"
              minPosition -3.14
              maxPosition 3.14
            }
            PositionSensor {
              name "encoder0"
            }
          ]
          endPoint Solid {
            translation 0 0 0.025
            children [
              Shape {
                appearance PBRAppearance {
                  baseColor 1 0 0
                }
                geometry Box {
                  size 0.4 0.01 0.01
                }
              }
              DEF joint_shape Shape {
                appearance PBRAppearance {
                  metalness 0
                }
                geometry Cylinder {
                  height 0.1
                  radius 0.04
                }
              }
              DEF base_joint1 Transform {
                translation 0 0 0.07
                rotation 1 0 0 1.57
                children [
                  USE joint_shape
                  DEF hj_shoulder2 HingeJoint {
                    jointParameters HingeJointParameters {
                      axis 0 0 1
                    }
                    device [
                      RotationalMotor {
                        name "motor1"
                        minPosition -1.75
                        maxPosition 1.75
                      }
                      PositionSensor {
                        name "encoder1"
                      }
                    ]
                    endPoint Solid {
                      translation 6.344386831896803e-06 -4.063382961159346e-06 -6.0069854897009355e-09
                      children [
                        Transform {
                          translation 0 0 0.05
                          rotation 0 0 1 1.57
                          children [
                            Shape {
                              appearance PBRAppearance {
                                baseColor 1 0 0
                              }
                              geometry Box {
                                size 0.08 0.01 0.01
                              }
                            }
                          ]
                        }
                        Transform {
                          translation 0 0.15 0
                          children [
                            DEF upperarm Shape {
                              appearance PBRAppearance {
                                baseColor 1 0.5 0
                                metalness 0.9
                              }
                              geometry Box {
                                size 0.04 0.3 0.04
                              }
                            }
                          ]
                        }
                        DEF sh2_elbow Transform {
                          translation 0 0.3 0
                          children [
                            USE joint_shape
                            DEF hj_elbow HingeJoint {
                              jointParameters HingeJointParameters {
                                axis 0 0 1
                              }
                              device [
                                RotationalMotor {
                                  name "motor2"
                                  minPosition -2.5
                                  maxPosition 2.5
                                }
                                PositionSensor {
                                  name "encoder2"
                                }
                              ]
                              endPoint Solid {
                                children [
                                  Transform {
                                    translation 0 0 0.05
                                    rotation 0 0 1 1.57
                                    children [
                                      Shape {
                                        appearance PBRAppearance {
                                          baseColor 1 0 0
                                        }
                                        geometry Box {
                                          size 0.08 0.01 0.01
                                        }
                                      }
                                    ]
                                  }
                                  Transform {
                                    translation 0 0.125 0
                                    children [
                                      DEF forearm Shape {
                                        appearance PBRAppearance {
                                          baseColor 1 0.5 0
                                          metalness 0.5
                                        }
                                        geometry Box {
                                          size 0.04 0.25 0.04
                                        }
                                      }
                                    ]
                                  }
                                  DEF elbow_wrist Transform {
                                    translation 0 0.25 0
                                    children [
                                      Shape {
                                        appearance PBRAppearance {
                                          baseColor 0 1 0
                                          roughness 1
                                          metalness 0.1
                                        }
                                        geometry Sphere {
                                          radius 0.03
                                        }
                                      }
                                      GPS {
                                        name "ee_pose_sensor"
                                      }
                                      InertialUnit {
                                        name "ee_pose_sensor2"
                                      }
                                    ]
                                  }
                                ]
                                immersionProperties [
                                  ImmersionProperties {
                                  }
                                ]
                                boundingObject Transform {
                                  translation 0 0.125 0
                                  children [
                                    DEF forearm Shape {
                                      appearance PBRAppearance {
                                      }
                                      geometry Box {
                                        size 0.04 0.25 0.04
                                      }
                                    }
                                  ]
                                }
                                physics Physics {
                                }
                              }
                            }
                          ]
                        }
                      ]
                      immersionProperties [
                        ImmersionProperties {
                        }
                      ]
                      boundingObject Transform {
                        translation 0 0.15 0
                        children [
                          DEF upperarm Shape {
                            appearance PBRAppearance {
                            }
                            geometry Box {
                              size 0.04 0.3 0.04
                            }
                          }
                        ]
                      }
                      physics Physics {
                      }
                    }
                  }
                ]
              }
            ]
            immersionProperties [
              ImmersionProperties {
              }
            ]
            boundingObject DEF joint_shape Shape {
              appearance PBRAppearance {
              }
              geometry Cylinder {
                height 0.1
                radius 0.04
              }
            }
            physics Physics {
            }
          }
        }
      ]
    }
  ]
  boundingObject Transform {
    translation 0 0.025 0
    rotation 1 0 0 -1.57
    children [
      USE base
    ]
  }
  physics Physics {
  }
  controller "<extern>"
  supervisor TRUE
  synchronization FALSE
}
DEF draw_trj Shape {
  appearance Appearance {
    material Material {
      diffuseColor 1 0 0
      emissiveColor 1 0 0
    }
  }
  geometry DEF TRJ_LINE_SET IndexedLineSet {
    coord Coordinate {
      point [
        0 0 0
        0 0 0
        0 0 0
        0 0 0
        0 0 0
        0 0 0
        0 0 0
        0 0 0
        0 0 0
        0 0 0
        0 0 0
        0 0 0
      ]
    }
    coordIndex [
      0, 0, 0, 0, 0, 0, 0, 0, 0, 0
    ]
  }
}
